2025-05-09 17:32:23,582 - uvicorn.error - ERROR - Traceback (most recent call last):
  File "C:\Users\Basudev Samanta\AppData\Local\Programs\Python\Python310\lib\asyncio\runners.py", line 44, in run
    return loop.run_until_complete(main)
  File "C:\Users\Basudev Samanta\AppData\Local\Programs\Python\Python310\lib\asyncio\base_events.py", line 636, in run_until_complete
    self.run_forever()
  File "C:\Users\Basudev Samanta\AppData\Local\Programs\Python\Python310\lib\asyncio\base_events.py", line 603, in run_forever
    self._run_once()
  File "C:\Users\Basudev Samanta\AppData\Local\Programs\Python\Python310\lib\asyncio\base_events.py", line 1899, in _run_once
    handle._run()
  File "C:\Users\Basudev Samanta\AppData\Local\Programs\Python\Python310\lib\asyncio\events.py", line 80, in _run
    self._context.run(self._callback, *self._args)
  File "D:\main-company\Projects\talentsync_helper\main_upload\.venv\lib\site-packages\uvicorn\server.py", line 69, in serve
    with self.capture_signals():
  File "C:\Users\Basudev Samanta\AppData\Local\Programs\Python\Python310\lib\contextlib.py", line 142, in __exit__
    next(self.gen)
  File "D:\main-company\Projects\talentsync_helper\main_upload\.venv\lib\site-packages\uvicorn\server.py", line 330, in capture_signals
    signal.raise_signal(captured_signal)
KeyboardInterrupt

During handling of the above exception, another exception occurred:

Traceback (most recent call last):
  File "D:\main-company\Projects\talentsync_helper\main_upload\.venv\lib\site-packages\starlette\routing.py", line 699, in lifespan
    await receive()
  File "D:\main-company\Projects\talentsync_helper\main_upload\.venv\lib\site-packages\uvicorn\lifespan\on.py", line 137, in receive
    return await self.receive_queue.get()
  File "C:\Users\Basudev Samanta\AppData\Local\Programs\Python\Python310\lib\asyncio\queues.py", line 159, in get
    await getter
asyncio.exceptions.CancelledError

2025-05-09 18:10:54,329 - uvicorn.error - ERROR - Traceback (most recent call last):
  File "C:\Users\Basudev Samanta\AppData\Local\Programs\Python\Python310\lib\asyncio\runners.py", line 44, in run
    return loop.run_until_complete(main)
  File "C:\Users\Basudev Samanta\AppData\Local\Programs\Python\Python310\lib\asyncio\base_events.py", line 636, in run_until_complete
    self.run_forever()
  File "C:\Users\Basudev Samanta\AppData\Local\Programs\Python\Python310\lib\asyncio\base_events.py", line 603, in run_forever
    self._run_once()
  File "C:\Users\Basudev Samanta\AppData\Local\Programs\Python\Python310\lib\asyncio\base_events.py", line 1899, in _run_once
    handle._run()
  File "C:\Users\Basudev Samanta\AppData\Local\Programs\Python\Python310\lib\asyncio\events.py", line 80, in _run
    self._context.run(self._callback, *self._args)
  File "D:\main-company\Projects\talentsync_helper\main_upload\.venv\lib\site-packages\uvicorn\server.py", line 69, in serve
    with self.capture_signals():
  File "C:\Users\Basudev Samanta\AppData\Local\Programs\Python\Python310\lib\contextlib.py", line 142, in __exit__
    next(self.gen)
  File "D:\main-company\Projects\talentsync_helper\main_upload\.venv\lib\site-packages\uvicorn\server.py", line 330, in capture_signals
    signal.raise_signal(captured_signal)
KeyboardInterrupt

During handling of the above exception, another exception occurred:

Traceback (most recent call last):
  File "D:\main-company\Projects\talentsync_helper\main_upload\.venv\lib\site-packages\starlette\routing.py", line 699, in lifespan
    await receive()
  File "D:\main-company\Projects\talentsync_helper\main_upload\.venv\lib\site-packages\uvicorn\lifespan\on.py", line 137, in receive
    return await self.receive_queue.get()
  File "C:\Users\Basudev Samanta\AppData\Local\Programs\Python\Python310\lib\asyncio\queues.py", line 159, in get
    await getter
asyncio.exceptions.CancelledError

2025-05-09 18:13:58,388 - uvicorn.error - ERROR - Exception in ASGI application
Traceback (most recent call last):
  File "D:\main-company\Projects\talentsync_helper\main_upload\.venv\lib\site-packages\uvicorn\protocols\http\httptools_impl.py", line 409, in run_asgi
    result = await app(  # type: ignore[func-returns-value]
  File "D:\main-company\Projects\talentsync_helper\main_upload\.venv\lib\site-packages\uvicorn\middleware\proxy_headers.py", line 60, in __call__
    return await self.app(scope, receive, send)
  File "D:\main-company\Projects\talentsync_helper\main_upload\.venv\lib\site-packages\fastapi\applications.py", line 1054, in __call__
    await super().__call__(scope, receive, send)
  File "D:\main-company\Projects\talentsync_helper\main_upload\.venv\lib\site-packages\starlette\applications.py", line 112, in __call__
    await self.middleware_stack(scope, receive, send)
  File "D:\main-company\Projects\talentsync_helper\main_upload\.venv\lib\site-packages\starlette\middleware\errors.py", line 187, in __call__
    raise exc
  File "D:\main-company\Projects\talentsync_helper\main_upload\.venv\lib\site-packages\starlette\middleware\errors.py", line 165, in __call__
    await self.app(scope, receive, _send)
  File "D:\main-company\Projects\talentsync_helper\main_upload\.venv\lib\site-packages\starlette\middleware\exceptions.py", line 62, in __call__
    await wrap_app_handling_exceptions(self.app, conn)(scope, receive, send)
  File "D:\main-company\Projects\talentsync_helper\main_upload\.venv\lib\site-packages\starlette\_exception_handler.py", line 53, in wrapped_app
    raise exc
  File "D:\main-company\Projects\talentsync_helper\main_upload\.venv\lib\site-packages\starlette\_exception_handler.py", line 42, in wrapped_app
    await app(scope, receive, sender)
  File "D:\main-company\Projects\talentsync_helper\main_upload\.venv\lib\site-packages\starlette\routing.py", line 714, in __call__
    await self.middleware_stack(scope, receive, send)
  File "D:\main-company\Projects\talentsync_helper\main_upload\.venv\lib\site-packages\starlette\routing.py", line 734, in app
    await route.handle(scope, receive, send)
  File "D:\main-company\Projects\talentsync_helper\main_upload\.venv\lib\site-packages\starlette\routing.py", line 288, in handle
    await self.app(scope, receive, send)
  File "D:\main-company\Projects\talentsync_helper\main_upload\.venv\lib\site-packages\starlette\routing.py", line 76, in app
    await wrap_app_handling_exceptions(app, request)(scope, receive, send)
  File "D:\main-company\Projects\talentsync_helper\main_upload\.venv\lib\site-packages\starlette\_exception_handler.py", line 53, in wrapped_app
    raise exc
  File "D:\main-company\Projects\talentsync_helper\main_upload\.venv\lib\site-packages\starlette\_exception_handler.py", line 42, in wrapped_app
    await app(scope, receive, sender)
  File "D:\main-company\Projects\talentsync_helper\main_upload\.venv\lib\site-packages\starlette\routing.py", line 73, in app
    response = await f(request)
  File "D:\main-company\Projects\talentsync_helper\main_upload\.venv\lib\site-packages\fastapi\routing.py", line 291, in app
    solved_result = await solve_dependencies(
  File "D:\main-company\Projects\talentsync_helper\main_upload\.venv\lib\site-packages\fastapi\dependencies\utils.py", line 638, in solve_dependencies
    solved = await call(**solved_result.values)
  File "D:\main-company\Projects\talentsync_helper\main_upload\backend\api\deps.py", line 111, in get_api_key_data
    return UserData(
  File "C:\Users\Basudev Samanta\AppData\Local\Programs\Python\Python310\lib\typing.py", line 955, in __call__
    raise TypeError(f"Type {self._name} cannot be instantiated; "
TypeError: Type Tuple cannot be instantiated; use tuple() instead
2025-05-09 19:36:49,563 - uvicorn.error - ERROR - Traceback (most recent call last):
  File "C:\Users\Basudev Samanta\AppData\Local\Programs\Python\Python310\lib\asyncio\runners.py", line 44, in run
    return loop.run_until_complete(main)
  File "C:\Users\Basudev Samanta\AppData\Local\Programs\Python\Python310\lib\asyncio\base_events.py", line 636, in run_until_complete
    self.run_forever()
  File "C:\Users\Basudev Samanta\AppData\Local\Programs\Python\Python310\lib\asyncio\base_events.py", line 603, in run_forever
    self._run_once()
  File "C:\Users\Basudev Samanta\AppData\Local\Programs\Python\Python310\lib\asyncio\base_events.py", line 1899, in _run_once
    handle._run()
  File "C:\Users\Basudev Samanta\AppData\Local\Programs\Python\Python310\lib\asyncio\events.py", line 80, in _run
    self._context.run(self._callback, *self._args)
  File "D:\main-company\Projects\talentsync_helper\main_upload\.venv\lib\site-packages\uvicorn\server.py", line 69, in serve
    with self.capture_signals():
  File "C:\Users\Basudev Samanta\AppData\Local\Programs\Python\Python310\lib\contextlib.py", line 142, in __exit__
    next(self.gen)
  File "D:\main-company\Projects\talentsync_helper\main_upload\.venv\lib\site-packages\uvicorn\server.py", line 330, in capture_signals
    signal.raise_signal(captured_signal)
KeyboardInterrupt

During handling of the above exception, another exception occurred:

Traceback (most recent call last):
  File "D:\main-company\Projects\talentsync_helper\main_upload\.venv\lib\site-packages\starlette\routing.py", line 699, in lifespan
    await receive()
  File "D:\main-company\Projects\talentsync_helper\main_upload\.venv\lib\site-packages\uvicorn\lifespan\on.py", line 137, in receive
    return await self.receive_queue.get()
  File "C:\Users\Basudev Samanta\AppData\Local\Programs\Python\Python310\lib\asyncio\queues.py", line 159, in get
    await getter
asyncio.exceptions.CancelledError

