2025-05-11 00:30:23,632 - uvicorn.error - ERROR - Exception in ASGI application
Traceback (most recent call last):
  File "D:\Company[Klizo]\projects\talentsync_helper\upload_main\main-upload-benchmark\.venv\lib\site-packages\uvicorn\protocols\http\httptools_impl.py", line 409, in run_asgi
    result = await app(  # type: ignore[func-returns-value]
  File "D:\Company[Klizo]\projects\talentsync_helper\upload_main\main-upload-benchmark\.venv\lib\site-packages\uvicorn\middleware\proxy_headers.py", line 60, in __call__
    return await self.app(scope, receive, send)
  File "D:\Company[Klizo]\projects\talentsync_helper\upload_main\main-upload-benchmark\.venv\lib\site-packages\fastapi\applications.py", line 1054, in __call__
    await super().__call__(scope, receive, send)
  File "D:\Company[Klizo]\projects\talentsync_helper\upload_main\main-upload-benchmark\.venv\lib\site-packages\starlette\applications.py", line 112, in __call__
    await self.middleware_stack(scope, receive, send)
  File "D:\Company[Klizo]\projects\talentsync_helper\upload_main\main-upload-benchmark\.venv\lib\site-packages\starlette\middleware\errors.py", line 187, in __call__
    raise exc
  File "D:\Company[Klizo]\projects\talentsync_helper\upload_main\main-upload-benchmark\.venv\lib\site-packages\starlette\middleware\errors.py", line 165, in __call__
    await self.app(scope, receive, _send)
  File "D:\Company[Klizo]\projects\talentsync_helper\upload_main\main-upload-benchmark\.venv\lib\site-packages\starlette\middleware\exceptions.py", line 62, in __call__
    await wrap_app_handling_exceptions(self.app, conn)(scope, receive, send)
  File "D:\Company[Klizo]\projects\talentsync_helper\upload_main\main-upload-benchmark\.venv\lib\site-packages\starlette\_exception_handler.py", line 53, in wrapped_app
    raise exc
  File "D:\Company[Klizo]\projects\talentsync_helper\upload_main\main-upload-benchmark\.venv\lib\site-packages\starlette\_exception_handler.py", line 42, in wrapped_app
    await app(scope, receive, sender)
  File "D:\Company[Klizo]\projects\talentsync_helper\upload_main\main-upload-benchmark\.venv\lib\site-packages\starlette\routing.py", line 714, in __call__
    await self.middleware_stack(scope, receive, send)
  File "D:\Company[Klizo]\projects\talentsync_helper\upload_main\main-upload-benchmark\.venv\lib\site-packages\starlette\routing.py", line 734, in app
    await route.handle(scope, receive, send)
  File "D:\Company[Klizo]\projects\talentsync_helper\upload_main\main-upload-benchmark\.venv\lib\site-packages\starlette\routing.py", line 288, in handle
    await self.app(scope, receive, send)
  File "D:\Company[Klizo]\projects\talentsync_helper\upload_main\main-upload-benchmark\.venv\lib\site-packages\starlette\routing.py", line 76, in app
    await wrap_app_handling_exceptions(app, request)(scope, receive, send)
  File "D:\Company[Klizo]\projects\talentsync_helper\upload_main\main-upload-benchmark\.venv\lib\site-packages\starlette\_exception_handler.py", line 53, in wrapped_app
    raise exc
  File "D:\Company[Klizo]\projects\talentsync_helper\upload_main\main-upload-benchmark\.venv\lib\site-packages\starlette\_exception_handler.py", line 42, in wrapped_app
    await app(scope, receive, sender)
  File "D:\Company[Klizo]\projects\talentsync_helper\upload_main\main-upload-benchmark\.venv\lib\site-packages\starlette\routing.py", line 73, in app
    response = await f(request)
  File "D:\Company[Klizo]\projects\talentsync_helper\upload_main\main-upload-benchmark\.venv\lib\site-packages\fastapi\routing.py", line 291, in app
    solved_result = await solve_dependencies(
  File "D:\Company[Klizo]\projects\talentsync_helper\upload_main\main-upload-benchmark\.venv\lib\site-packages\fastapi\dependencies\utils.py", line 638, in solve_dependencies
    solved = await call(**solved_result.values)
  File "D:\Company[Klizo]\projects\talentsync_helper\upload_main\main-upload-benchmark\backend\api\deps.py", line 111, in get_api_key_data
    return UserData(
  File "C:\Users\saman\AppData\Local\Programs\Python\Python310\lib\typing.py", line 955, in __call__
    raise TypeError(f"Type {self._name} cannot be instantiated; "
TypeError: Type Tuple cannot be instantiated; use tuple() instead
2025-05-11 00:47:50,630 - uvicorn.error - ERROR - Exception in ASGI application
Traceback (most recent call last):
  File "D:\Company[Klizo]\projects\talentsync_helper\upload_main\main-upload-benchmark\.venv\lib\site-packages\uvicorn\protocols\http\httptools_impl.py", line 409, in run_asgi
    result = await app(  # type: ignore[func-returns-value]
  File "D:\Company[Klizo]\projects\talentsync_helper\upload_main\main-upload-benchmark\.venv\lib\site-packages\uvicorn\middleware\proxy_headers.py", line 60, in __call__
    return await self.app(scope, receive, send)
  File "D:\Company[Klizo]\projects\talentsync_helper\upload_main\main-upload-benchmark\.venv\lib\site-packages\fastapi\applications.py", line 1054, in __call__
    await super().__call__(scope, receive, send)
  File "D:\Company[Klizo]\projects\talentsync_helper\upload_main\main-upload-benchmark\.venv\lib\site-packages\starlette\applications.py", line 112, in __call__
    await self.middleware_stack(scope, receive, send)
  File "D:\Company[Klizo]\projects\talentsync_helper\upload_main\main-upload-benchmark\.venv\lib\site-packages\starlette\middleware\errors.py", line 187, in __call__
    raise exc
  File "D:\Company[Klizo]\projects\talentsync_helper\upload_main\main-upload-benchmark\.venv\lib\site-packages\starlette\middleware\errors.py", line 165, in __call__
    await self.app(scope, receive, _send)
  File "D:\Company[Klizo]\projects\talentsync_helper\upload_main\main-upload-benchmark\.venv\lib\site-packages\starlette\middleware\exceptions.py", line 62, in __call__
    await wrap_app_handling_exceptions(self.app, conn)(scope, receive, send)
  File "D:\Company[Klizo]\projects\talentsync_helper\upload_main\main-upload-benchmark\.venv\lib\site-packages\starlette\_exception_handler.py", line 53, in wrapped_app
    raise exc
  File "D:\Company[Klizo]\projects\talentsync_helper\upload_main\main-upload-benchmark\.venv\lib\site-packages\starlette\_exception_handler.py", line 42, in wrapped_app
    await app(scope, receive, sender)
  File "D:\Company[Klizo]\projects\talentsync_helper\upload_main\main-upload-benchmark\.venv\lib\site-packages\starlette\routing.py", line 714, in __call__
    await self.middleware_stack(scope, receive, send)
  File "D:\Company[Klizo]\projects\talentsync_helper\upload_main\main-upload-benchmark\.venv\lib\site-packages\starlette\routing.py", line 734, in app
    await route.handle(scope, receive, send)
  File "D:\Company[Klizo]\projects\talentsync_helper\upload_main\main-upload-benchmark\.venv\lib\site-packages\starlette\routing.py", line 288, in handle
    await self.app(scope, receive, send)
  File "D:\Company[Klizo]\projects\talentsync_helper\upload_main\main-upload-benchmark\.venv\lib\site-packages\starlette\routing.py", line 76, in app
    await wrap_app_handling_exceptions(app, request)(scope, receive, send)
  File "D:\Company[Klizo]\projects\talentsync_helper\upload_main\main-upload-benchmark\.venv\lib\site-packages\starlette\_exception_handler.py", line 53, in wrapped_app
    raise exc
  File "D:\Company[Klizo]\projects\talentsync_helper\upload_main\main-upload-benchmark\.venv\lib\site-packages\starlette\_exception_handler.py", line 42, in wrapped_app
    await app(scope, receive, sender)
  File "D:\Company[Klizo]\projects\talentsync_helper\upload_main\main-upload-benchmark\.venv\lib\site-packages\starlette\routing.py", line 73, in app
    response = await f(request)
  File "D:\Company[Klizo]\projects\talentsync_helper\upload_main\main-upload-benchmark\.venv\lib\site-packages\fastapi\routing.py", line 291, in app
    solved_result = await solve_dependencies(
  File "D:\Company[Klizo]\projects\talentsync_helper\upload_main\main-upload-benchmark\.venv\lib\site-packages\fastapi\dependencies\utils.py", line 638, in solve_dependencies
    solved = await call(**solved_result.values)
  File "D:\Company[Klizo]\projects\talentsync_helper\upload_main\main-upload-benchmark\backend\api\deps.py", line 111, in get_api_key_data
    return UserData(
  File "C:\Users\saman\AppData\Local\Programs\Python\Python310\lib\typing.py", line 955, in __call__
    raise TypeError(f"Type {self._name} cannot be instantiated; "
TypeError: Type Tuple cannot be instantiated; use tuple() instead
2025-05-11 01:27:37,681 - uvicorn.error - ERROR - Traceback (most recent call last):
  File "C:\Users\saman\AppData\Local\Programs\Python\Python310\lib\asyncio\runners.py", line 44, in run
    return loop.run_until_complete(main)
  File "C:\Users\saman\AppData\Local\Programs\Python\Python310\lib\asyncio\base_events.py", line 636, in run_until_complete
    self.run_forever()
  File "C:\Users\saman\AppData\Local\Programs\Python\Python310\lib\asyncio\base_events.py", line 603, in run_forever
    self._run_once()
  File "C:\Users\saman\AppData\Local\Programs\Python\Python310\lib\asyncio\base_events.py", line 1899, in _run_once
    handle._run()
  File "C:\Users\saman\AppData\Local\Programs\Python\Python310\lib\asyncio\events.py", line 80, in _run
    self._context.run(self._callback, *self._args)
  File "D:\Company[Klizo]\projects\talentsync_helper\upload_main\main-upload-benchmark\.venv\lib\site-packages\uvicorn\server.py", line 69, in serve
    with self.capture_signals():
  File "C:\Users\saman\AppData\Local\Programs\Python\Python310\lib\contextlib.py", line 142, in __exit__
    next(self.gen)
  File "D:\Company[Klizo]\projects\talentsync_helper\upload_main\main-upload-benchmark\.venv\lib\site-packages\uvicorn\server.py", line 330, in capture_signals
    signal.raise_signal(captured_signal)
KeyboardInterrupt

During handling of the above exception, another exception occurred:

Traceback (most recent call last):
  File "D:\Company[Klizo]\projects\talentsync_helper\upload_main\main-upload-benchmark\.venv\lib\site-packages\starlette\routing.py", line 699, in lifespan
    await receive()
  File "D:\Company[Klizo]\projects\talentsync_helper\upload_main\main-upload-benchmark\.venv\lib\site-packages\uvicorn\lifespan\on.py", line 137, in receive
    return await self.receive_queue.get()
  File "C:\Users\saman\AppData\Local\Programs\Python\Python310\lib\asyncio\queues.py", line 159, in get
    await getter
asyncio.exceptions.CancelledError

2025-05-11 01:28:23,742 - uvicorn.error - ERROR - Exception in ASGI application
Traceback (most recent call last):
  File "D:\Company[Klizo]\projects\talentsync_helper\upload_main\main-upload-benchmark\.venv\lib\site-packages\uvicorn\protocols\http\httptools_impl.py", line 409, in run_asgi
    result = await app(  # type: ignore[func-returns-value]
  File "D:\Company[Klizo]\projects\talentsync_helper\upload_main\main-upload-benchmark\.venv\lib\site-packages\uvicorn\middleware\proxy_headers.py", line 60, in __call__
    return await self.app(scope, receive, send)
  File "D:\Company[Klizo]\projects\talentsync_helper\upload_main\main-upload-benchmark\.venv\lib\site-packages\fastapi\applications.py", line 1054, in __call__
    await super().__call__(scope, receive, send)
  File "D:\Company[Klizo]\projects\talentsync_helper\upload_main\main-upload-benchmark\.venv\lib\site-packages\starlette\applications.py", line 112, in __call__
    await self.middleware_stack(scope, receive, send)
  File "D:\Company[Klizo]\projects\talentsync_helper\upload_main\main-upload-benchmark\.venv\lib\site-packages\starlette\middleware\errors.py", line 187, in __call__
    raise exc
  File "D:\Company[Klizo]\projects\talentsync_helper\upload_main\main-upload-benchmark\.venv\lib\site-packages\starlette\middleware\errors.py", line 165, in __call__
    await self.app(scope, receive, _send)
  File "D:\Company[Klizo]\projects\talentsync_helper\upload_main\main-upload-benchmark\.venv\lib\site-packages\starlette\middleware\exceptions.py", line 62, in __call__
    await wrap_app_handling_exceptions(self.app, conn)(scope, receive, send)
  File "D:\Company[Klizo]\projects\talentsync_helper\upload_main\main-upload-benchmark\.venv\lib\site-packages\starlette\_exception_handler.py", line 53, in wrapped_app
    raise exc
  File "D:\Company[Klizo]\projects\talentsync_helper\upload_main\main-upload-benchmark\.venv\lib\site-packages\starlette\_exception_handler.py", line 42, in wrapped_app
    await app(scope, receive, sender)
  File "D:\Company[Klizo]\projects\talentsync_helper\upload_main\main-upload-benchmark\.venv\lib\site-packages\starlette\routing.py", line 714, in __call__
    await self.middleware_stack(scope, receive, send)
  File "D:\Company[Klizo]\projects\talentsync_helper\upload_main\main-upload-benchmark\.venv\lib\site-packages\starlette\routing.py", line 734, in app
    await route.handle(scope, receive, send)
  File "D:\Company[Klizo]\projects\talentsync_helper\upload_main\main-upload-benchmark\.venv\lib\site-packages\starlette\routing.py", line 288, in handle
    await self.app(scope, receive, send)
  File "D:\Company[Klizo]\projects\talentsync_helper\upload_main\main-upload-benchmark\.venv\lib\site-packages\starlette\routing.py", line 76, in app
    await wrap_app_handling_exceptions(app, request)(scope, receive, send)
  File "D:\Company[Klizo]\projects\talentsync_helper\upload_main\main-upload-benchmark\.venv\lib\site-packages\starlette\_exception_handler.py", line 53, in wrapped_app
    raise exc
  File "D:\Company[Klizo]\projects\talentsync_helper\upload_main\main-upload-benchmark\.venv\lib\site-packages\starlette\_exception_handler.py", line 42, in wrapped_app
    await app(scope, receive, sender)
  File "D:\Company[Klizo]\projects\talentsync_helper\upload_main\main-upload-benchmark\.venv\lib\site-packages\starlette\routing.py", line 73, in app
    response = await f(request)
  File "D:\Company[Klizo]\projects\talentsync_helper\upload_main\main-upload-benchmark\.venv\lib\site-packages\fastapi\routing.py", line 301, in app
    raw_response = await run_endpoint_function(
  File "D:\Company[Klizo]\projects\talentsync_helper\upload_main\main-upload-benchmark\.venv\lib\site-packages\fastapi\routing.py", line 212, in run_endpoint_function
    return await dependant.call(**values)
  File "D:\Company[Klizo]\projects\talentsync_helper\upload_main\main-upload-benchmark\backend\upload\upload.py", line 61, in upload_candidates
    if await batches.find_one({"batch_name": batch_name}):
  File "C:\Users\saman\AppData\Local\Programs\Python\Python310\lib\concurrent\futures\thread.py", line 58, in run
    result = self.fn(*self.args, **self.kwargs)
  File "D:\Company[Klizo]\projects\talentsync_helper\upload_main\main-upload-benchmark\.venv\lib\site-packages\pymongo\synchronous\collection.py", line 1755, in find_one
    for result in cursor.limit(-1):
  File "D:\Company[Klizo]\projects\talentsync_helper\upload_main\main-upload-benchmark\.venv\lib\site-packages\pymongo\synchronous\cursor.py", line 1284, in __next__
    return self.next()
  File "D:\Company[Klizo]\projects\talentsync_helper\upload_main\main-upload-benchmark\.venv\lib\site-packages\pymongo\synchronous\cursor.py", line 1260, in next
    if len(self._data) or self._refresh():
  File "D:\Company[Klizo]\projects\talentsync_helper\upload_main\main-upload-benchmark\.venv\lib\site-packages\pymongo\synchronous\cursor.py", line 1208, in _refresh
    self._send_message(q)
  File "D:\Company[Klizo]\projects\talentsync_helper\upload_main\main-upload-benchmark\.venv\lib\site-packages\pymongo\synchronous\cursor.py", line 1102, in _send_message
    response = client._run_operation(
  File "D:\Company[Klizo]\projects\talentsync_helper\upload_main\main-upload-benchmark\.venv\lib\site-packages\pymongo\_csot.py", line 119, in csot_wrapper
    return func(self, *args, **kwargs)
  File "D:\Company[Klizo]\projects\talentsync_helper\upload_main\main-upload-benchmark\.venv\lib\site-packages\pymongo\synchronous\mongo_client.py", line 1917, in _run_operation
    return self._retryable_read(
  File "D:\Company[Klizo]\projects\talentsync_helper\upload_main\main-upload-benchmark\.venv\lib\site-packages\pymongo\synchronous\mongo_client.py", line 2026, in _retryable_read
    return self._retry_internal(
  File "D:\Company[Klizo]\projects\talentsync_helper\upload_main\main-upload-benchmark\.venv\lib\site-packages\pymongo\_csot.py", line 119, in csot_wrapper
    return func(self, *args, **kwargs)
  File "D:\Company[Klizo]\projects\talentsync_helper\upload_main\main-upload-benchmark\.venv\lib\site-packages\pymongo\synchronous\mongo_client.py", line 1993, in _retry_internal
    ).run()
  File "D:\Company[Klizo]\projects\talentsync_helper\upload_main\main-upload-benchmark\.venv\lib\site-packages\pymongo\synchronous\mongo_client.py", line 2730, in run
    return self._read() if self._is_read else self._write()
  File "D:\Company[Klizo]\projects\talentsync_helper\upload_main\main-upload-benchmark\.venv\lib\site-packages\pymongo\synchronous\mongo_client.py", line 2875, in _read
    self._server = self._get_server()
  File "D:\Company[Klizo]\projects\talentsync_helper\upload_main\main-upload-benchmark\.venv\lib\site-packages\pymongo\synchronous\mongo_client.py", line 2823, in _get_server
    return self._client._select_server(
  File "D:\Company[Klizo]\projects\talentsync_helper\upload_main\main-upload-benchmark\.venv\lib\site-packages\pymongo\synchronous\mongo_client.py", line 1812, in _select_server
    server = topology.select_server(
  File "D:\Company[Klizo]\projects\talentsync_helper\upload_main\main-upload-benchmark\.venv\lib\site-packages\pymongo\synchronous\topology.py", line 409, in select_server
    server = self._select_server(
  File "D:\Company[Klizo]\projects\talentsync_helper\upload_main\main-upload-benchmark\.venv\lib\site-packages\pymongo\synchronous\topology.py", line 387, in _select_server
    servers = self.select_servers(
  File "D:\Company[Klizo]\projects\talentsync_helper\upload_main\main-upload-benchmark\.venv\lib\site-packages\pymongo\synchronous\topology.py", line 294, in select_servers
    server_descriptions = self._select_servers_loop(
  File "D:\Company[Klizo]\projects\talentsync_helper\upload_main\main-upload-benchmark\.venv\lib\site-packages\pymongo\synchronous\topology.py", line 344, in _select_servers_loop
    raise ServerSelectionTimeoutError(
pymongo.errors.ServerSelectionTimeoutError: 172.21.192.1:27017: timed out (configured timeouts: socketTimeoutMS: 20000.0ms, connectTimeoutMS: 20000.0ms), Timeout: 30s, Topology Description: <TopologyDescription id: 681fafb4eadf01a6bdb77f67, topology_type: Unknown, servers: [<ServerDescription ('172.21.192.1', 27017) server_type: Unknown, rtt: None, error=NetworkTimeout('172.21.192.1:27017: timed out (configured timeouts: socketTimeoutMS: 20000.0ms, connectTimeoutMS: 20000.0ms)')>]>
2025-05-11 01:36:15,909 - uvicorn.error - ERROR - Exception in ASGI application
Traceback (most recent call last):
  File "D:\Company[Klizo]\projects\talentsync_helper\upload_main\main-upload-benchmark\.venv\lib\site-packages\uvicorn\protocols\http\httptools_impl.py", line 409, in run_asgi
    result = await app(  # type: ignore[func-returns-value]
  File "D:\Company[Klizo]\projects\talentsync_helper\upload_main\main-upload-benchmark\.venv\lib\site-packages\uvicorn\middleware\proxy_headers.py", line 60, in __call__
    return await self.app(scope, receive, send)
  File "D:\Company[Klizo]\projects\talentsync_helper\upload_main\main-upload-benchmark\.venv\lib\site-packages\fastapi\applications.py", line 1054, in __call__
    await super().__call__(scope, receive, send)
  File "D:\Company[Klizo]\projects\talentsync_helper\upload_main\main-upload-benchmark\.venv\lib\site-packages\starlette\applications.py", line 112, in __call__
    await self.middleware_stack(scope, receive, send)
  File "D:\Company[Klizo]\projects\talentsync_helper\upload_main\main-upload-benchmark\.venv\lib\site-packages\starlette\middleware\errors.py", line 187, in __call__
    raise exc
  File "D:\Company[Klizo]\projects\talentsync_helper\upload_main\main-upload-benchmark\.venv\lib\site-packages\starlette\middleware\errors.py", line 165, in __call__
    await self.app(scope, receive, _send)
  File "D:\Company[Klizo]\projects\talentsync_helper\upload_main\main-upload-benchmark\.venv\lib\site-packages\starlette\middleware\exceptions.py", line 62, in __call__
    await wrap_app_handling_exceptions(self.app, conn)(scope, receive, send)
  File "D:\Company[Klizo]\projects\talentsync_helper\upload_main\main-upload-benchmark\.venv\lib\site-packages\starlette\_exception_handler.py", line 53, in wrapped_app
    raise exc
  File "D:\Company[Klizo]\projects\talentsync_helper\upload_main\main-upload-benchmark\.venv\lib\site-packages\starlette\_exception_handler.py", line 42, in wrapped_app
    await app(scope, receive, sender)
  File "D:\Company[Klizo]\projects\talentsync_helper\upload_main\main-upload-benchmark\.venv\lib\site-packages\starlette\routing.py", line 714, in __call__
    await self.middleware_stack(scope, receive, send)
  File "D:\Company[Klizo]\projects\talentsync_helper\upload_main\main-upload-benchmark\.venv\lib\site-packages\starlette\routing.py", line 734, in app
    await route.handle(scope, receive, send)
  File "D:\Company[Klizo]\projects\talentsync_helper\upload_main\main-upload-benchmark\.venv\lib\site-packages\starlette\routing.py", line 288, in handle
    await self.app(scope, receive, send)
  File "D:\Company[Klizo]\projects\talentsync_helper\upload_main\main-upload-benchmark\.venv\lib\site-packages\starlette\routing.py", line 76, in app
    await wrap_app_handling_exceptions(app, request)(scope, receive, send)
  File "D:\Company[Klizo]\projects\talentsync_helper\upload_main\main-upload-benchmark\.venv\lib\site-packages\starlette\_exception_handler.py", line 53, in wrapped_app
    raise exc
  File "D:\Company[Klizo]\projects\talentsync_helper\upload_main\main-upload-benchmark\.venv\lib\site-packages\starlette\_exception_handler.py", line 42, in wrapped_app
    await app(scope, receive, sender)
  File "D:\Company[Klizo]\projects\talentsync_helper\upload_main\main-upload-benchmark\.venv\lib\site-packages\starlette\routing.py", line 73, in app
    response = await f(request)
  File "D:\Company[Klizo]\projects\talentsync_helper\upload_main\main-upload-benchmark\.venv\lib\site-packages\fastapi\routing.py", line 301, in app
    raw_response = await run_endpoint_function(
  File "D:\Company[Klizo]\projects\talentsync_helper\upload_main\main-upload-benchmark\.venv\lib\site-packages\fastapi\routing.py", line 212, in run_endpoint_function
    return await dependant.call(**values)
  File "D:\Company[Klizo]\projects\talentsync_helper\upload_main\main-upload-benchmark\backend\upload\upload.py", line 61, in upload_candidates
    if await batches.find_one({"batch_name": batch_name}):
  File "C:\Users\saman\AppData\Local\Programs\Python\Python310\lib\concurrent\futures\thread.py", line 58, in run
    result = self.fn(*self.args, **self.kwargs)
  File "D:\Company[Klizo]\projects\talentsync_helper\upload_main\main-upload-benchmark\.venv\lib\site-packages\pymongo\synchronous\collection.py", line 1755, in find_one
    for result in cursor.limit(-1):
  File "D:\Company[Klizo]\projects\talentsync_helper\upload_main\main-upload-benchmark\.venv\lib\site-packages\pymongo\synchronous\cursor.py", line 1284, in __next__
    return self.next()
  File "D:\Company[Klizo]\projects\talentsync_helper\upload_main\main-upload-benchmark\.venv\lib\site-packages\pymongo\synchronous\cursor.py", line 1260, in next
    if len(self._data) or self._refresh():
  File "D:\Company[Klizo]\projects\talentsync_helper\upload_main\main-upload-benchmark\.venv\lib\site-packages\pymongo\synchronous\cursor.py", line 1208, in _refresh
    self._send_message(q)
  File "D:\Company[Klizo]\projects\talentsync_helper\upload_main\main-upload-benchmark\.venv\lib\site-packages\pymongo\synchronous\cursor.py", line 1102, in _send_message
    response = client._run_operation(
  File "D:\Company[Klizo]\projects\talentsync_helper\upload_main\main-upload-benchmark\.venv\lib\site-packages\pymongo\_csot.py", line 119, in csot_wrapper
    return func(self, *args, **kwargs)
  File "D:\Company[Klizo]\projects\talentsync_helper\upload_main\main-upload-benchmark\.venv\lib\site-packages\pymongo\synchronous\mongo_client.py", line 1917, in _run_operation
    return self._retryable_read(
  File "D:\Company[Klizo]\projects\talentsync_helper\upload_main\main-upload-benchmark\.venv\lib\site-packages\pymongo\synchronous\mongo_client.py", line 2026, in _retryable_read
    return self._retry_internal(
  File "D:\Company[Klizo]\projects\talentsync_helper\upload_main\main-upload-benchmark\.venv\lib\site-packages\pymongo\_csot.py", line 119, in csot_wrapper
    return func(self, *args, **kwargs)
  File "D:\Company[Klizo]\projects\talentsync_helper\upload_main\main-upload-benchmark\.venv\lib\site-packages\pymongo\synchronous\mongo_client.py", line 1993, in _retry_internal
    ).run()
  File "D:\Company[Klizo]\projects\talentsync_helper\upload_main\main-upload-benchmark\.venv\lib\site-packages\pymongo\synchronous\mongo_client.py", line 2730, in run
    return self._read() if self._is_read else self._write()
  File "D:\Company[Klizo]\projects\talentsync_helper\upload_main\main-upload-benchmark\.venv\lib\site-packages\pymongo\synchronous\mongo_client.py", line 2875, in _read
    self._server = self._get_server()
  File "D:\Company[Klizo]\projects\talentsync_helper\upload_main\main-upload-benchmark\.venv\lib\site-packages\pymongo\synchronous\mongo_client.py", line 2823, in _get_server
    return self._client._select_server(
  File "D:\Company[Klizo]\projects\talentsync_helper\upload_main\main-upload-benchmark\.venv\lib\site-packages\pymongo\synchronous\mongo_client.py", line 1812, in _select_server
    server = topology.select_server(
  File "D:\Company[Klizo]\projects\talentsync_helper\upload_main\main-upload-benchmark\.venv\lib\site-packages\pymongo\synchronous\topology.py", line 409, in select_server
    server = self._select_server(
  File "D:\Company[Klizo]\projects\talentsync_helper\upload_main\main-upload-benchmark\.venv\lib\site-packages\pymongo\synchronous\topology.py", line 387, in _select_server
    servers = self.select_servers(
  File "D:\Company[Klizo]\projects\talentsync_helper\upload_main\main-upload-benchmark\.venv\lib\site-packages\pymongo\synchronous\topology.py", line 294, in select_servers
    server_descriptions = self._select_servers_loop(
  File "D:\Company[Klizo]\projects\talentsync_helper\upload_main\main-upload-benchmark\.venv\lib\site-packages\pymongo\synchronous\topology.py", line 344, in _select_servers_loop
    raise ServerSelectionTimeoutError(
pymongo.errors.ServerSelectionTimeoutError: 172.21.192.1:27017: timed out (configured timeouts: socketTimeoutMS: 20000.0ms, connectTimeoutMS: 20000.0ms), Timeout: 30s, Topology Description: <TopologyDescription id: 681fb10eb1c393b282a2ad9e, topology_type: Unknown, servers: [<ServerDescription ('172.21.192.1', 27017) server_type: Unknown, rtt: None, error=NetworkTimeout('172.21.192.1:27017: timed out (configured timeouts: socketTimeoutMS: 20000.0ms, connectTimeoutMS: 20000.0ms)')>]>
2025-05-11 01:36:46,118 - uvicorn - ERROR - Error getting JSON for key job:job_001: unknown command 'JSON.GET', with args beginning with: 'job:job_001' '.' 
2025-05-11 01:36:46,122 - uvicorn.error - ERROR - Exception in ASGI application
Traceback (most recent call last):
  File "D:\Company[Klizo]\projects\talentsync_helper\upload_main\main-upload-benchmark\.venv\lib\site-packages\uvicorn\protocols\http\httptools_impl.py", line 409, in run_asgi
    result = await app(  # type: ignore[func-returns-value]
  File "D:\Company[Klizo]\projects\talentsync_helper\upload_main\main-upload-benchmark\.venv\lib\site-packages\uvicorn\middleware\proxy_headers.py", line 60, in __call__
    return await self.app(scope, receive, send)
  File "D:\Company[Klizo]\projects\talentsync_helper\upload_main\main-upload-benchmark\.venv\lib\site-packages\fastapi\applications.py", line 1054, in __call__
    await super().__call__(scope, receive, send)
  File "D:\Company[Klizo]\projects\talentsync_helper\upload_main\main-upload-benchmark\.venv\lib\site-packages\starlette\applications.py", line 112, in __call__
    await self.middleware_stack(scope, receive, send)
  File "D:\Company[Klizo]\projects\talentsync_helper\upload_main\main-upload-benchmark\.venv\lib\site-packages\starlette\middleware\errors.py", line 187, in __call__
    raise exc
  File "D:\Company[Klizo]\projects\talentsync_helper\upload_main\main-upload-benchmark\.venv\lib\site-packages\starlette\middleware\errors.py", line 165, in __call__
    await self.app(scope, receive, _send)
  File "D:\Company[Klizo]\projects\talentsync_helper\upload_main\main-upload-benchmark\.venv\lib\site-packages\starlette\middleware\exceptions.py", line 62, in __call__
    await wrap_app_handling_exceptions(self.app, conn)(scope, receive, send)
  File "D:\Company[Klizo]\projects\talentsync_helper\upload_main\main-upload-benchmark\.venv\lib\site-packages\starlette\_exception_handler.py", line 53, in wrapped_app
    raise exc
  File "D:\Company[Klizo]\projects\talentsync_helper\upload_main\main-upload-benchmark\.venv\lib\site-packages\starlette\_exception_handler.py", line 42, in wrapped_app
    await app(scope, receive, sender)
  File "D:\Company[Klizo]\projects\talentsync_helper\upload_main\main-upload-benchmark\.venv\lib\site-packages\starlette\routing.py", line 714, in __call__
    await self.middleware_stack(scope, receive, send)
  File "D:\Company[Klizo]\projects\talentsync_helper\upload_main\main-upload-benchmark\.venv\lib\site-packages\starlette\routing.py", line 734, in app
    await route.handle(scope, receive, send)
  File "D:\Company[Klizo]\projects\talentsync_helper\upload_main\main-upload-benchmark\.venv\lib\site-packages\starlette\routing.py", line 288, in handle
    await self.app(scope, receive, send)
  File "D:\Company[Klizo]\projects\talentsync_helper\upload_main\main-upload-benchmark\.venv\lib\site-packages\starlette\routing.py", line 76, in app
    await wrap_app_handling_exceptions(app, request)(scope, receive, send)
  File "D:\Company[Klizo]\projects\talentsync_helper\upload_main\main-upload-benchmark\.venv\lib\site-packages\starlette\_exception_handler.py", line 53, in wrapped_app
    raise exc
  File "D:\Company[Klizo]\projects\talentsync_helper\upload_main\main-upload-benchmark\.venv\lib\site-packages\starlette\_exception_handler.py", line 42, in wrapped_app
    await app(scope, receive, sender)
  File "D:\Company[Klizo]\projects\talentsync_helper\upload_main\main-upload-benchmark\.venv\lib\site-packages\starlette\routing.py", line 73, in app
    response = await f(request)
  File "D:\Company[Klizo]\projects\talentsync_helper\upload_main\main-upload-benchmark\.venv\lib\site-packages\fastapi\routing.py", line 301, in app
    raw_response = await run_endpoint_function(
  File "D:\Company[Klizo]\projects\talentsync_helper\upload_main\main-upload-benchmark\.venv\lib\site-packages\fastapi\routing.py", line 212, in run_endpoint_function
    return await dependant.call(**values)
  File "D:\Company[Klizo]\projects\talentsync_helper\upload_main\main-upload-benchmark\backend\upload\upload.py", line 68, in upload_candidates
    job = await get_job_data(job_id)
  File "D:\Company[Klizo]\projects\talentsync_helper\upload_main\main-upload-benchmark\backend\upload\utils.py", line 58, in get_job_data
    if redis.get_json_(redis_key):
  File "D:\Company[Klizo]\projects\talentsync_helper\upload_main\main-upload-benchmark\backend\redis_config\redis.py", line 92, in get_json_
    return self.redis.json().get(key, path)
  File "D:\Company[Klizo]\projects\talentsync_helper\upload_main\main-upload-benchmark\.venv\lib\site-packages\redis\commands\json\commands.py", line 202, in get
    return self.execute_command("JSON.GET", *pieces, keys=[name])
  File "D:\Company[Klizo]\projects\talentsync_helper\upload_main\main-upload-benchmark\.venv\lib\site-packages\redis\client.py", line 621, in execute_command
    return self._execute_command(*args, **options)
  File "D:\Company[Klizo]\projects\talentsync_helper\upload_main\main-upload-benchmark\.venv\lib\site-packages\redis\client.py", line 632, in _execute_command
    return conn.retry.call_with_retry(
  File "D:\Company[Klizo]\projects\talentsync_helper\upload_main\main-upload-benchmark\.venv\lib\site-packages\redis\retry.py", line 74, in call_with_retry
    return do()
  File "D:\Company[Klizo]\projects\talentsync_helper\upload_main\main-upload-benchmark\.venv\lib\site-packages\redis\client.py", line 633, in <lambda>
    lambda: self._send_command_parse_response(
  File "D:\Company[Klizo]\projects\talentsync_helper\upload_main\main-upload-benchmark\.venv\lib\site-packages\redis\client.py", line 604, in _send_command_parse_response
    return self.parse_response(conn, command_name, **options)
  File "D:\Company[Klizo]\projects\talentsync_helper\upload_main\main-upload-benchmark\.venv\lib\site-packages\redis\client.py", line 651, in parse_response
    response = connection.read_response()
  File "D:\Company[Klizo]\projects\talentsync_helper\upload_main\main-upload-benchmark\.venv\lib\site-packages\redis\connection.py", line 666, in read_response
    raise response
redis.exceptions.ResponseError: unknown command 'JSON.GET', with args beginning with: 'job:job_001' '.' 
2025-05-11 01:42:42,047 - uvicorn - ERROR - Error getting JSON for key job:job_001: unknown command 'JSON.GET', with args beginning with: 'job:job_001' '.' 
2025-05-11 01:42:42,052 - uvicorn.error - ERROR - Exception in ASGI application
Traceback (most recent call last):
  File "D:\Company[Klizo]\projects\talentsync_helper\upload_main\main-upload-benchmark\.venv\lib\site-packages\uvicorn\protocols\http\httptools_impl.py", line 409, in run_asgi
    result = await app(  # type: ignore[func-returns-value]
  File "D:\Company[Klizo]\projects\talentsync_helper\upload_main\main-upload-benchmark\.venv\lib\site-packages\uvicorn\middleware\proxy_headers.py", line 60, in __call__
    return await self.app(scope, receive, send)
  File "D:\Company[Klizo]\projects\talentsync_helper\upload_main\main-upload-benchmark\.venv\lib\site-packages\fastapi\applications.py", line 1054, in __call__
    await super().__call__(scope, receive, send)
  File "D:\Company[Klizo]\projects\talentsync_helper\upload_main\main-upload-benchmark\.venv\lib\site-packages\starlette\applications.py", line 112, in __call__
    await self.middleware_stack(scope, receive, send)
  File "D:\Company[Klizo]\projects\talentsync_helper\upload_main\main-upload-benchmark\.venv\lib\site-packages\starlette\middleware\errors.py", line 187, in __call__
    raise exc
  File "D:\Company[Klizo]\projects\talentsync_helper\upload_main\main-upload-benchmark\.venv\lib\site-packages\starlette\middleware\errors.py", line 165, in __call__
    await self.app(scope, receive, _send)
  File "D:\Company[Klizo]\projects\talentsync_helper\upload_main\main-upload-benchmark\.venv\lib\site-packages\starlette\middleware\exceptions.py", line 62, in __call__
    await wrap_app_handling_exceptions(self.app, conn)(scope, receive, send)
  File "D:\Company[Klizo]\projects\talentsync_helper\upload_main\main-upload-benchmark\.venv\lib\site-packages\starlette\_exception_handler.py", line 53, in wrapped_app
    raise exc
  File "D:\Company[Klizo]\projects\talentsync_helper\upload_main\main-upload-benchmark\.venv\lib\site-packages\starlette\_exception_handler.py", line 42, in wrapped_app
    await app(scope, receive, sender)
  File "D:\Company[Klizo]\projects\talentsync_helper\upload_main\main-upload-benchmark\.venv\lib\site-packages\starlette\routing.py", line 714, in __call__
    await self.middleware_stack(scope, receive, send)
  File "D:\Company[Klizo]\projects\talentsync_helper\upload_main\main-upload-benchmark\.venv\lib\site-packages\starlette\routing.py", line 734, in app
    await route.handle(scope, receive, send)
  File "D:\Company[Klizo]\projects\talentsync_helper\upload_main\main-upload-benchmark\.venv\lib\site-packages\starlette\routing.py", line 288, in handle
    await self.app(scope, receive, send)
  File "D:\Company[Klizo]\projects\talentsync_helper\upload_main\main-upload-benchmark\.venv\lib\site-packages\starlette\routing.py", line 76, in app
    await wrap_app_handling_exceptions(app, request)(scope, receive, send)
  File "D:\Company[Klizo]\projects\talentsync_helper\upload_main\main-upload-benchmark\.venv\lib\site-packages\starlette\_exception_handler.py", line 53, in wrapped_app
    raise exc
  File "D:\Company[Klizo]\projects\talentsync_helper\upload_main\main-upload-benchmark\.venv\lib\site-packages\starlette\_exception_handler.py", line 42, in wrapped_app
    await app(scope, receive, sender)
  File "D:\Company[Klizo]\projects\talentsync_helper\upload_main\main-upload-benchmark\.venv\lib\site-packages\starlette\routing.py", line 73, in app
    response = await f(request)
  File "D:\Company[Klizo]\projects\talentsync_helper\upload_main\main-upload-benchmark\.venv\lib\site-packages\fastapi\routing.py", line 301, in app
    raw_response = await run_endpoint_function(
  File "D:\Company[Klizo]\projects\talentsync_helper\upload_main\main-upload-benchmark\.venv\lib\site-packages\fastapi\routing.py", line 212, in run_endpoint_function
    return await dependant.call(**values)
  File "D:\Company[Klizo]\projects\talentsync_helper\upload_main\main-upload-benchmark\backend\upload\upload.py", line 68, in upload_candidates
    job = await get_job_data(job_id)
  File "D:\Company[Klizo]\projects\talentsync_helper\upload_main\main-upload-benchmark\backend\upload\utils.py", line 58, in get_job_data
    if redis.get_json_(redis_key):
  File "D:\Company[Klizo]\projects\talentsync_helper\upload_main\main-upload-benchmark\backend\redis_config\redis.py", line 92, in get_json_
    return self.redis.json().get(key, path)
  File "D:\Company[Klizo]\projects\talentsync_helper\upload_main\main-upload-benchmark\.venv\lib\site-packages\redis\commands\json\commands.py", line 202, in get
    return self.execute_command("JSON.GET", *pieces, keys=[name])
  File "D:\Company[Klizo]\projects\talentsync_helper\upload_main\main-upload-benchmark\.venv\lib\site-packages\redis\client.py", line 621, in execute_command
    return self._execute_command(*args, **options)
  File "D:\Company[Klizo]\projects\talentsync_helper\upload_main\main-upload-benchmark\.venv\lib\site-packages\redis\client.py", line 632, in _execute_command
    return conn.retry.call_with_retry(
  File "D:\Company[Klizo]\projects\talentsync_helper\upload_main\main-upload-benchmark\.venv\lib\site-packages\redis\retry.py", line 74, in call_with_retry
    return do()
  File "D:\Company[Klizo]\projects\talentsync_helper\upload_main\main-upload-benchmark\.venv\lib\site-packages\redis\client.py", line 633, in <lambda>
    lambda: self._send_command_parse_response(
  File "D:\Company[Klizo]\projects\talentsync_helper\upload_main\main-upload-benchmark\.venv\lib\site-packages\redis\client.py", line 604, in _send_command_parse_response
    return self.parse_response(conn, command_name, **options)
  File "D:\Company[Klizo]\projects\talentsync_helper\upload_main\main-upload-benchmark\.venv\lib\site-packages\redis\client.py", line 651, in parse_response
    response = connection.read_response()
  File "D:\Company[Klizo]\projects\talentsync_helper\upload_main\main-upload-benchmark\.venv\lib\site-packages\redis\connection.py", line 666, in read_response
    raise response
redis.exceptions.ResponseError: unknown command 'JSON.GET', with args beginning with: 'job:job_001' '.' 
2025-05-11 23:37:06,135 - uvicorn - ERROR - Error getting JSON for key job:job_001: unknown command 'JSON.GET', with args beginning with: 'job:job_001' '.' 
2025-05-11 23:37:06,151 - uvicorn.error - ERROR - Exception in ASGI application
Traceback (most recent call last):
  File "D:\Company[Klizo]\projects\talentsync_helper\upload_main\main-upload-benchmark\.venv\lib\site-packages\uvicorn\protocols\http\httptools_impl.py", line 409, in run_asgi
    result = await app(  # type: ignore[func-returns-value]
  File "D:\Company[Klizo]\projects\talentsync_helper\upload_main\main-upload-benchmark\.venv\lib\site-packages\uvicorn\middleware\proxy_headers.py", line 60, in __call__
    return await self.app(scope, receive, send)
  File "D:\Company[Klizo]\projects\talentsync_helper\upload_main\main-upload-benchmark\.venv\lib\site-packages\fastapi\applications.py", line 1054, in __call__
    await super().__call__(scope, receive, send)
  File "D:\Company[Klizo]\projects\talentsync_helper\upload_main\main-upload-benchmark\.venv\lib\site-packages\starlette\applications.py", line 112, in __call__
    await self.middleware_stack(scope, receive, send)
  File "D:\Company[Klizo]\projects\talentsync_helper\upload_main\main-upload-benchmark\.venv\lib\site-packages\starlette\middleware\errors.py", line 187, in __call__
    raise exc
  File "D:\Company[Klizo]\projects\talentsync_helper\upload_main\main-upload-benchmark\.venv\lib\site-packages\starlette\middleware\errors.py", line 165, in __call__
    await self.app(scope, receive, _send)
  File "D:\Company[Klizo]\projects\talentsync_helper\upload_main\main-upload-benchmark\.venv\lib\site-packages\starlette\middleware\exceptions.py", line 62, in __call__
    await wrap_app_handling_exceptions(self.app, conn)(scope, receive, send)
  File "D:\Company[Klizo]\projects\talentsync_helper\upload_main\main-upload-benchmark\.venv\lib\site-packages\starlette\_exception_handler.py", line 53, in wrapped_app
    raise exc
  File "D:\Company[Klizo]\projects\talentsync_helper\upload_main\main-upload-benchmark\.venv\lib\site-packages\starlette\_exception_handler.py", line 42, in wrapped_app
    await app(scope, receive, sender)
  File "D:\Company[Klizo]\projects\talentsync_helper\upload_main\main-upload-benchmark\.venv\lib\site-packages\starlette\routing.py", line 714, in __call__
    await self.middleware_stack(scope, receive, send)
  File "D:\Company[Klizo]\projects\talentsync_helper\upload_main\main-upload-benchmark\.venv\lib\site-packages\starlette\routing.py", line 734, in app
    await route.handle(scope, receive, send)
  File "D:\Company[Klizo]\projects\talentsync_helper\upload_main\main-upload-benchmark\.venv\lib\site-packages\starlette\routing.py", line 288, in handle
    await self.app(scope, receive, send)
  File "D:\Company[Klizo]\projects\talentsync_helper\upload_main\main-upload-benchmark\.venv\lib\site-packages\starlette\routing.py", line 76, in app
    await wrap_app_handling_exceptions(app, request)(scope, receive, send)
  File "D:\Company[Klizo]\projects\talentsync_helper\upload_main\main-upload-benchmark\.venv\lib\site-packages\starlette\_exception_handler.py", line 53, in wrapped_app
    raise exc
  File "D:\Company[Klizo]\projects\talentsync_helper\upload_main\main-upload-benchmark\.venv\lib\site-packages\starlette\_exception_handler.py", line 42, in wrapped_app
    await app(scope, receive, sender)
  File "D:\Company[Klizo]\projects\talentsync_helper\upload_main\main-upload-benchmark\.venv\lib\site-packages\starlette\routing.py", line 73, in app
    response = await f(request)
  File "D:\Company[Klizo]\projects\talentsync_helper\upload_main\main-upload-benchmark\.venv\lib\site-packages\fastapi\routing.py", line 301, in app
    raw_response = await run_endpoint_function(
  File "D:\Company[Klizo]\projects\talentsync_helper\upload_main\main-upload-benchmark\.venv\lib\site-packages\fastapi\routing.py", line 212, in run_endpoint_function
    return await dependant.call(**values)
  File "D:\Company[Klizo]\projects\talentsync_helper\upload_main\main-upload-benchmark\backend\upload\upload.py", line 68, in upload_candidates
    job = await get_job_data(job_id)
  File "D:\Company[Klizo]\projects\talentsync_helper\upload_main\main-upload-benchmark\backend\upload\utils.py", line 58, in get_job_data
    if redis.get_json_(redis_key):
  File "D:\Company[Klizo]\projects\talentsync_helper\upload_main\main-upload-benchmark\backend\redis_config\redis.py", line 92, in get_json_
    return self.redis.json().get(key, path)
  File "D:\Company[Klizo]\projects\talentsync_helper\upload_main\main-upload-benchmark\.venv\lib\site-packages\redis\commands\json\commands.py", line 202, in get
    return self.execute_command("JSON.GET", *pieces, keys=[name])
  File "D:\Company[Klizo]\projects\talentsync_helper\upload_main\main-upload-benchmark\.venv\lib\site-packages\redis\client.py", line 621, in execute_command
    return self._execute_command(*args, **options)
  File "D:\Company[Klizo]\projects\talentsync_helper\upload_main\main-upload-benchmark\.venv\lib\site-packages\redis\client.py", line 632, in _execute_command
    return conn.retry.call_with_retry(
  File "D:\Company[Klizo]\projects\talentsync_helper\upload_main\main-upload-benchmark\.venv\lib\site-packages\redis\retry.py", line 74, in call_with_retry
    return do()
  File "D:\Company[Klizo]\projects\talentsync_helper\upload_main\main-upload-benchmark\.venv\lib\site-packages\redis\client.py", line 633, in <lambda>
    lambda: self._send_command_parse_response(
  File "D:\Company[Klizo]\projects\talentsync_helper\upload_main\main-upload-benchmark\.venv\lib\site-packages\redis\client.py", line 604, in _send_command_parse_response
    return self.parse_response(conn, command_name, **options)
  File "D:\Company[Klizo]\projects\talentsync_helper\upload_main\main-upload-benchmark\.venv\lib\site-packages\redis\client.py", line 651, in parse_response
    response = connection.read_response()
  File "D:\Company[Klizo]\projects\talentsync_helper\upload_main\main-upload-benchmark\.venv\lib\site-packages\redis\connection.py", line 666, in read_response
    raise response
redis.exceptions.ResponseError: unknown command 'JSON.GET', with args beginning with: 'job:job_001' '.' 


from here 

